Internal Server Error: /moesibert/banking/account/comdirect/
Traceback (most recent call last):
  File "C:\Users\Daniel\Envs\financeenv\lib\site-packages\django\core\handlers\exception.py", line 41, in inner
    response = get_response(request)
  File "C:\Users\Daniel\Envs\financeenv\lib\site-packages\django\core\handlers\base.py", line 217, in _get_response
    response = self.process_exception_by_middleware(e, request)
  File "C:\Users\Daniel\Envs\financeenv\lib\site-packages\django\core\handlers\base.py", line 215, in _get_response
    response = response.render()
  File "C:\Users\Daniel\Envs\financeenv\lib\site-packages\django\template\response.py", line 107, in render
    self.content = self.rendered_content
  File "C:\Users\Daniel\Envs\financeenv\lib\site-packages\django\template\response.py", line 84, in rendered_content
    content = template.render(context, self._request)
  File "C:\Users\Daniel\Envs\financeenv\lib\site-packages\django\template\backends\jinja2.py", line 81, in render
    return self.template.render(context)
  File "C:\Users\Daniel\Envs\financeenv\lib\site-packages\jinja2\asyncsupport.py", line 76, in render
    return original_render(self, *args, **kwargs)
  File "C:\Users\Daniel\Envs\financeenv\lib\site-packages\jinja2\environment.py", line 1008, in render
    return self.environment.handle_exception(exc_info, True)
  File "C:\Users\Daniel\Envs\financeenv\lib\site-packages\jinja2\environment.py", line 780, in handle_exception
    reraise(exc_type, exc_value, tb)
  File "C:\Users\Daniel\Envs\financeenv\lib\site-packages\jinja2\_compat.py", line 37, in reraise
    raise value.with_traceback(tb)
  File "C:\Users\Daniel\Desktop\mill\finance_project\finance\finance\templates\banking_account.njk", line 7, in top-level template code
    {% set title="Account " + account.name + " | Banking" %}
  File "C:\Users\Daniel\Desktop\mill\finance_project\finance\finance\templates\static\lm.njk", line 1, in top-level template code
    {% extends "static/base.njk" %}
  File "C:\Users\Daniel\Desktop\mill\finance_project\finance\finance\templates\static\base.njk", line 25, in top-level template code
    {% block body %}
  File "C:\Users\Daniel\Desktop\mill\finance_project\finance\finance\templates\static\lm.njk", line 17, in block "body"
    {% block main %}
  File "C:\Users\Daniel\Desktop\mill\finance_project\finance\finance\templates\banking_account.njk", line 115, in block "main"
    {{ table.row([change.get_date(user), change.get_balance(), change.get_description(), change.change, tablebuttons | safe]) }}
TypeError: get_balance() missing 1 required positional argument: 'movie'
"GET /moesibert/banking/account/comdirect/ HTTP/1.1" 500 171884
Internal Server Error: /moesibert/banking/
Traceback (most recent call last):
  File "C:\Users\Daniel\Envs\financeenv\lib\site-packages\django\core\handlers\exception.py", line 41, in inner
    response = get_response(request)
  File "C:\Users\Daniel\Envs\financeenv\lib\site-packages\django\core\handlers\base.py", line 217, in _get_response
    response = self.process_exception_by_middleware(e, request)
  File "C:\Users\Daniel\Envs\financeenv\lib\site-packages\django\core\handlers\base.py", line 215, in _get_response
    response = response.render()
  File "C:\Users\Daniel\Envs\financeenv\lib\site-packages\django\template\response.py", line 107, in render
    self.content = self.rendered_content
  File "C:\Users\Daniel\Envs\financeenv\lib\site-packages\django\template\response.py", line 84, in rendered_content
    content = template.render(context, self._request)
  File "C:\Users\Daniel\Envs\financeenv\lib\site-packages\django\template\backends\jinja2.py", line 81, in render
    return self.template.render(context)
  File "C:\Users\Daniel\Envs\financeenv\lib\site-packages\jinja2\asyncsupport.py", line 76, in render
    return original_render(self, *args, **kwargs)
  File "C:\Users\Daniel\Envs\financeenv\lib\site-packages\jinja2\environment.py", line 1008, in render
    return self.environment.handle_exception(exc_info, True)
  File "C:\Users\Daniel\Envs\financeenv\lib\site-packages\jinja2\environment.py", line 780, in handle_exception
    reraise(exc_type, exc_value, tb)
  File "C:\Users\Daniel\Envs\financeenv\lib\site-packages\jinja2\_compat.py", line 37, in reraise
    raise value.with_traceback(tb)
  File "C:\Users\Daniel\Desktop\mill\finance_project\finance\finance\templates\banking_index.njk", line 7, in top-level template code
    {% set title="Banking" %}
  File "C:\Users\Daniel\Desktop\mill\finance_project\finance\finance\templates\static\lm.njk", line 1, in top-level template code
    {% extends "static/base.njk" %}
  File "C:\Users\Daniel\Desktop\mill\finance_project\finance\finance\templates\static\base.njk", line 25, in top-level template code
    {% block body %}
  File "C:\Users\Daniel\Desktop\mill\finance_project\finance\finance\templates\static\lm.njk", line 17, in block "body"
    {% block main %}
  File "C:\Users\Daniel\Desktop\mill\finance_project\finance\finance\templates\banking_index.njk", line 68, in block "main"
    {{ movie.get_values(user, ["b",])["b"] }} {{ user.currency }}
  File "C:\Users\Daniel\Desktop\mill\finance_project\finance\finance\banking\models.py", line 239, in get_values
    end_picture = self.pictures.latest("d", "pk")
  File "C:\Users\Daniel\Envs\financeenv\lib\site-packages\django\db\models\manager.py", line 85, in manager_method
    return getattr(self.get_queryset(), name)(*args, **kwargs)
TypeError: latest() takes from 1 to 2 positional arguments but 3 were given
"GET /moesibert/banking/ HTTP/1.1" 500 165457
